<?xml version="1.0"?>
<robot name="trailer">

  <link name="base_footprint">
    <!-- <inertial>
      <mass value="0.0001"/>
      <origin xyz="0 0 0"/>
      <inertia ixx="0.0001" ixy="0.0" ixz="0.0" iyy="0.0001" iyz="0.0" izz="0.0001"/>
    </inertial>
    <visual>
      <origin rpy="0 0 0" xyz="0 0 0"/>
      <geometry>
        <box size="0.001 0.001 0.001"/>
      </geometry>
    </visual> -->
  </link>

  <joint name="base_footprint_joint" type="fixed">
    <origin rpy="0 0 0" xyz="0 0 0.07"/>
    <parent link="base_footprint"/>
    <child link="base_link"/>
  </joint>

  <link name="base_link">
    <visual>
      <geometry>
        <box size="0.5 0.06 0.03"/>
      </geometry>
      <material name="silver">
        <color rgba="0.75 0.75 0.75 1"/>
      </material>
    </visual>
    <collision>
      <geometry>
        <box size="0.5 0.06 0.03"/>
      </geometry>
    </collision>
    <inertial>
      <mass value="1.0"/>
      <inertia ixx="0.015" iyy="0.0375" izz="0.0375" ixy="0" ixz="0" iyz="0"/>
    </inertial>
  </link>

  <link name="cabin">
    <visual>
      <geometry>
        <box size="0.16 0.18 0.18"/>
      </geometry>
      <material name="red">
        <color rgba="1 0 0 1"/>
      </material>
    </visual>
    <collision>
      <geometry>
        <box size="0.16 0.18 0.18"/>
      </geometry>
    </collision>
    <inertial>
      <mass value="1.0"/>
      <inertia ixx="0.015" iyy="0.0375" izz="0.0375" ixy="0" ixz="0" iyz="0"/>
    </inertial>
  </link>

  <joint name="cabin_joint" type="fixed">
    <axis xyz="0 0 1"/>
    <parent link="base_link"/>
    <child link="cabin"/>
    <origin rpy="0 0 0" xyz="0.17 0 0.105"/>
  </joint>

  <!-- <link name="laser_frame">
    <collision>
      <geometry>
        <box size="0.72 0.72 0.42"/>
      </geometry>
    </collision>
    <visual>
      <geometry>
        <cylinder length="0.075" radius="0.042"/>
      </geometry>
      <material name="black">
        <color rgba="0 0 0 1"/>
      </material>
    </visual>
    <inertial>
      <mass value="0.1"/>
      <inertia ixx="5.1458e-5" iyy="5.1458e-5" izz="6.125e-5" ixy="0" ixz="0" iyz="0"/>
    </inertial>
  </link>

  <joint name="laser_joint" type="fixed">
    <axis xyz="0 0 1"/>
    <parent link="base_link"/>
    <child link="laser_frame"/>
    <origin rpy="-0.05 0.0 0.0" xyz="0.25 0.0 0.12"/>
  </joint> -->

  <link name="fr_wheel">
    <visual>
      <geometry>
        <cylinder length="0.02" radius="0.04"/>
      </geometry>
      <material name="black">
        <color rgba="0 0 0 1"/>
      </material>
    </visual>
    <collision>
      <geometry>
        <cylinder length="0.02" radius="0.04"/>
      </geometry>
    </collision>
    <inertial>
      <mass value="0.1"/>
      <inertia ixx="5.1458e-5" iyy="5.1458e-5" izz="6.125e-5" ixy="0" ixz="0" iyz="0"/>
    </inertial>
  </link>

  <joint name="fr_joint" type="continuous">
    <axis xyz="0 0 1"/>
    <parent link="base_link"/>
    <child link="fr_wheel"/>
    <origin rpy="-1.5708 0 0" xyz="0.15 -0.08 -.025"/>
  </joint>

  <link name="fl_wheel">
    <visual>
      <geometry>
        <cylinder length="0.02" radius="0.04"/>
      </geometry>
      <material name="black"/>
    </visual>
    <collision>
      <geometry>
        <cylinder length="0.02" radius="0.04"/>
      </geometry>
    </collision>
    <inertial>
      <mass value="0.1"/>
      <inertia ixx="5.1458e-5" iyy="5.1458e-5" izz="6.125e-5" ixy="0" ixz="0" iyz="0"/>
    </inertial>
  </link>

  <joint name="fl_joint" type="continuous">
    <axis xyz="0 0 1"/>
    <parent link="base_link"/>
    <child link="fl_wheel"/>
    <origin rpy="-1.5708 0 0" xyz="0.15 0.08 -.025"/>
  </joint>

  <link name="rr1_wheel">
    <visual>
      <geometry>
        <cylinder length="0.04" radius="0.04"/>
      </geometry>
      <material name="black">
        <color rgba="0 0 0 1"/>
      </material>
    </visual>
    <collision>
      <geometry>
        <cylinder length="0.04" radius="0.04"/>
      </geometry>
    </collision>
    <inertial>
      <mass value="0.1"/>
      <inertia ixx="5.1458e-5" iyy="5.1458e-5" izz="6.125e-5" ixy="0" ixz="0" iyz="0"/>
    </inertial>
  </link>

  <joint name="rr1_joint" type="continuous">
    <axis xyz="0 0 1"/>
    <parent link="base_link"/>
    <child link="rr1_wheel"/>
    <origin rpy="-1.5708 0 0" xyz="-0.08 -0.07 -.025"/>
  </joint>

  <link name="rr2_wheel">
    <visual>
      <geometry>
        <cylinder length="0.04" radius="0.04"/>
      </geometry>
      <material name="black">
        <color rgba="0 0 0 1"/>
      </material>
    </visual>
    <collision>
      <geometry>
        <cylinder length="0.04" radius="0.04"/>
      </geometry>
    </collision>
    <inertial>
      <mass value="0.1"/>
      <inertia ixx="5.1458e-5" iyy="5.1458e-5" izz="6.125e-5" ixy="0" ixz="0" iyz="0"/>
    </inertial>
  </link>

  <joint name="rr2_joint" type="continuous">
    <axis xyz="0 0 1"/>
    <parent link="base_link"/>
    <child link="rr2_wheel"/>
    <origin rpy="-1.5708 0 0" xyz="-0.18 -0.07 -.025"/>
  </joint>

  <link name="rl1_wheel">
    <visual>
      <geometry>
        <cylinder length="0.04" radius="0.04"/>
      </geometry>
      <material name="black">
        <color rgba="0 0 0 1"/>
      </material>
    </visual>
    <collision>
      <geometry>
        <cylinder length="0.04" radius="0.04"/>
      </geometry>
    </collision>
    <inertial>
      <mass value="0.1"/>
      <inertia ixx="5.1458e-5" iyy="5.1458e-5" izz="6.125e-5" ixy="0" ixz="0" iyz="0"/>
    </inertial>
  </link>

  <joint name="rl1_joint" type="continuous">
    <axis xyz="0 0 1"/>
    <parent link="base_link"/>
    <child link="rl1_wheel"/>
    <origin rpy="-1.5708 0 0" xyz="-0.08 0.07 -.025"/>
  </joint>

  <link name="rl2_wheel">
    <visual>
      <geometry>
        <cylinder length="0.04" radius="0.04"/>
      </geometry>
      <material name="black">
        <color rgba="0 0 0 1"/>
      </material>
    </visual>
    <collision>
      <geometry>
        <cylinder length="0.04" radius="0.04"/>
      </geometry>
    </collision>
    <inertial>
      <mass value="0.1"/>
      <inertia ixx="5.1458e-5" iyy="5.1458e-5" izz="6.125e-5" ixy="0" ixz="0" iyz="0"/>
    </inertial>
  </link>

  <joint name="rl2_joint" type="continuous">
    <axis xyz="0 0 1"/>
    <parent link="base_link"/>
    <child link="rl2_wheel"/>
    <origin rpy="-1.5708 0 0" xyz="-0.18 0.07 -.025"/>
  </joint>

  <!--
  <link name="trailer">
    <visual>
      <origin xyz="-0.38 0 0.1" rpy="0 0 0"/>
      <geometry>
        <box size="0.9 0.18 0.18"/>
      </geometry>
      <material name="silver"/>
    </visual>
    <collision>
      <origin xyz="-0.38 0 0.1" rpy="0 0 0"/>
      <geometry>
        <box size="0.9 0.18 0.18"/>
      </geometry>
    </collision>
    <inertial>
      <origin xyz="-0.38 0 0.1" rpy="0 0 0"/>
      <mass value="10.0"/>
      <inertia ixx="0.15" iyy="0.375" izz="0.375" ixy="0" ixz="0" iyz="0"/>
    </inertial>
  </link>

  <joint name="trailer_joint" type="fixed">
    <axis xyz="0 0 1"/>
    <parent link="base_link"/>
    <child link="trailer"/>
    <origin rpy="0 0 0" xyz="-0.17 0 0.035"/>
  </joint>

  <link name="tr1_wheel">
    <visual>
      <geometry>
        <cylinder length="0.04" radius="0.04"/>
      </geometry>
      <material name="black">
        <color rgba="0 0 0 1"/>
      </material>
    </visual>
    <collision>
      <geometry>
        <cylinder length="0.04" radius="0.04"/>
      </geometry>
    </collision>
    <inertial>
      <mass value="0.1"/>
      <inertia ixx="5.1458e-5" iyy="5.1458e-5" izz="6.125e-5" ixy="0" ixz="0" iyz="0"/>
    </inertial>
  </link>

  <joint name="tr1_joint" type="continuous">
    <axis xyz="0 0 1"/>
    <parent link="trailer"/>
    <child link="tr1_wheel"/>
    <origin rpy="-1.5708 0 0" xyz="-0.61 -0.07 -.06"/>
  </joint>

  <link name="tr2_wheel">
    <visual>
      <geometry>
        <cylinder length="0.04" radius="0.04"/>
      </geometry>
      <material name="black">
        <color rgba="0 0 0 1"/>
      </material>
    </visual>
    <collision>
      <geometry>
        <cylinder length="0.04" radius="0.04"/>
      </geometry>
    </collision>
    <inertial>
      <mass value="0.1"/>
      <inertia ixx="5.1458e-5" iyy="5.1458e-5" izz="6.125e-5" ixy="0" ixz="0" iyz="0"/>
    </inertial>
  </link>

  <joint name="tr2_joint" type="continuous">
    <axis xyz="0 0 1"/>
    <parent link="trailer"/>
    <child link="tr2_wheel"/>
    <origin rpy="-1.5708 0 0" xyz="-0.71 -0.07 -.06"/>
  </joint>

  <link name="tl1_wheel">
    <visual>
      <geometry>
        <cylinder length="0.04" radius="0.04"/>
      </geometry>
      <material name="black">
        <color rgba="0 0 0 1"/>
      </material>
    </visual>
    <collision>
      <geometry>
        <cylinder length="0.04" radius="0.04"/>
      </geometry>
    </collision>
    <inertial>
      <mass value="0.1"/>
      <inertia ixx="5.1458e-5" iyy="5.1458e-5" izz="6.125e-5" ixy="0" ixz="0" iyz="0"/>
    </inertial>
  </link>

  <joint name="tl1_joint" type="continuous">
    <axis xyz="0 0 1"/>
    <parent link="trailer"/>
    <child link="tl1_wheel"/>
    <origin rpy="-1.5708 0 0" xyz="-0.61 0.07 -.06"/>
  </joint>

  <link name="tl2_wheel">
    <visual>
      <geometry>
        <cylinder length="0.04" radius="0.04"/>
      </geometry>
      <material name="black">
        <color rgba="0 0 0 1"/>
      </material>
    </visual>
    <collision>
      <geometry>
        <cylinder length="0.04" radius="0.04"/>
      </geometry>
    </collision>
    <inertial>
      <mass value="0.1"/>
      <inertia ixx="5.1458e-5" iyy="5.1458e-5" izz="6.125e-5" ixy="0" ixz="0" iyz="0"/>
    </inertial>
  </link>

  <joint name="tl2_joint" type="continuous">
    <axis xyz="0 0 1"/>
    <parent link="trailer"/>
    <child link="tl2_wheel"/>
    <origin rpy="-1.5708 0 0" xyz="-0.71 0.07 -.06"/>
  </joint>
-->
</robot>
